<sdf version='1.7'>
  <world name='default'>
    <light name='sun' type='directional'>
      <cast_shadows>1</cast_shadows>
      <pose>0 0 10 0 -0 0</pose>
      <diffuse>0.8 0.8 0.8 1</diffuse>
      <specular>0.2 0.2 0.2 1</specular>
      <attenuation>
        <range>1000</range>
        <constant>0.9</constant>
        <linear>0.01</linear>
        <quadratic>0.001</quadratic>
      </attenuation>
      <direction>-0.5 0.1 -0.9</direction>
      <spot>
        <inner_angle>0</inner_angle>
        <outer_angle>0</outer_angle>
        <falloff>0</falloff>
      </spot>
    </light>
    <model name='ground_plane'>
      <static>1</static>
      <link name='link'>
        <collision name='collision'>
          <geometry>
            <plane>
              <normal>0 0 1</normal>
              <size>100 100</size>
            </plane>
          </geometry>
          <surface>
            <contact>
              <collide_bitmask>65535</collide_bitmask>
              <ode/>
            </contact>
            <friction>
              <ode>
                <mu>100</mu>
                <mu2>50</mu2>
              </ode>
              <torsional>
                <ode/>
              </torsional>
            </friction>
            <bounce/>
          </surface>
          <max_contacts>10</max_contacts>
        </collision>
        <visual name='visual'>
          <cast_shadows>0</cast_shadows>
          <geometry>
            <plane>
              <normal>0 0 1</normal>
              <size>100 100</size>
            </plane>
          </geometry>
          <material>
            <script>
              <uri>file://media/materials/scripts/gazebo.material</uri>
              <name>Gazebo/Grey</name>
            </script>
          </material>
        </visual>
        <self_collide>0</self_collide>
        <enable_wind>0</enable_wind>
        <kinematic>0</kinematic>
      </link>
    </model>
    <gravity>0 0 -9.8</gravity>
    <magnetic_field>6e-06 2.3e-05 -4.2e-05</magnetic_field>
    <atmosphere type='adiabatic'/>
    <physics type='ode'>
      <max_step_size>0.001</max_step_size>
      <real_time_factor>1</real_time_factor>
      <real_time_update_rate>1000</real_time_update_rate>
    </physics>
    <scene>
      <ambient>0.4 0.4 0.4 1</ambient>
      <background>0.7 0.7 0.7 1</background>
      <shadows>1</shadows>
    </scene>
    <wind/>
    <spherical_coordinates>
      <surface_model>EARTH_WGS84</surface_model>
      <latitude_deg>0</latitude_deg>
      <longitude_deg>0</longitude_deg>
      <elevation>0</elevation>
      <heading_deg>0</heading_deg>
    </spherical_coordinates>
    <model name='JetBot'>
      <static>0</static>
      <link name='chassis'>
        <pose>0 0 0.043 1.5708 -0 1.5708</pose>
        <collision name='collision'>
          <geometry>
            <mesh>
              <scale>0.001 0.001 0.001</scale>
              <uri>model://jetbot/meshes/JetBot-v3-Chassis.dae</uri>
            </mesh>
          </geometry>
          <surface>
            <friction>
              <ode>
                <mu>0</mu>
                <mu2>0</mu2>
                <slip1>1</slip1>
                <slip2>1</slip2>
              </ode>
              <torsional>
                <ode/>
              </torsional>
            </friction>
            <contact>
              <ode/>
            </contact>
            <bounce/>
          </surface>
          <max_contacts>10</max_contacts>
        </collision>
        <visual name='visual'>
          <geometry>
            <mesh>
              <scale>0.001 0.001 0.001</scale>
              <uri>model://jetbot/meshes/JetBot-v3-Chassis.dae</uri>
            </mesh>
          </geometry>
        </visual>
        <self_collide>0</self_collide>
        <inertial>
          <pose>0 0 0 0 -0 0</pose>
          <inertia>
            <ixx>1</ixx>
            <ixy>0</ixy>
            <ixz>0</ixz>
            <iyy>1</iyy>
            <iyz>0</iyz>
            <izz>1</izz>
          </inertia>
          <mass>1</mass>
        </inertial>
        <enable_wind>0</enable_wind>
        <kinematic>0</kinematic>
      </link>
      <link name='left_wheel'>
        <pose>0.03 0.05125 0.03 0 -0 1.5708</pose>
        <collision name='collision'>
          <geometry>
            <mesh>
              <scale>0.001 0.001 0.001</scale>
              <uri>model://jetbot/meshes/JetBot-v3-Wheel.stl</uri>
            </mesh>
          </geometry>
          <max_contacts>10</max_contacts>
          <surface>
            <contact>
              <ode/>
            </contact>
            <bounce/>
            <friction>
              <torsional>
                <ode/>
              </torsional>
              <ode/>
            </friction>
          </surface>
        </collision>
        <visual name='visual'>
          <geometry>
            <mesh>
              <scale>0.001 0.001 0.001</scale>
              <uri>model://jetbot/meshes/JetBot-v3-Wheel.stl</uri>
            </mesh>
          </geometry>
          <material>
            <ambient>0.1 0.1 0.1 1</ambient>
            <diffuse>0.1 0.1 0.1 1</diffuse>
            <specular>0 0 0 0</specular>
            <emissive>0 0 0 1</emissive>
          </material>
        </visual>
        <self_collide>0</self_collide>
        <inertial>
          <pose>0 0 0 0 -0 0</pose>
          <inertia>
            <ixx>1</ixx>
            <ixy>0</ixy>
            <ixz>0</ixz>
            <iyy>1</iyy>
            <iyz>0</iyz>
            <izz>1</izz>
          </inertia>
          <mass>1</mass>
        </inertial>
        <enable_wind>0</enable_wind>
        <kinematic>0</kinematic>
      </link>
      <link name='right_wheel'>
        <pose>0.03 -0.0595 0.03 0 -0 1.5708</pose>
        <collision name='collision'>
          <geometry>
            <mesh>
              <scale>0.001 0.001 0.001</scale>
              <uri>model://jetbot/meshes/JetBot-v3-Wheel.stl</uri>
            </mesh>
          </geometry>
          <max_contacts>10</max_contacts>
          <surface>
            <contact>
              <ode/>
            </contact>
            <bounce/>
            <friction>
              <torsional>
                <ode/>
              </torsional>
              <ode/>
            </friction>
          </surface>
        </collision>
        <visual name='visual'>
          <geometry>
            <mesh>
              <scale>0.001 0.001 0.001</scale>
              <uri>model://jetbot/meshes/JetBot-v3-Wheel.stl</uri>
            </mesh>
          </geometry>
          <material>
            <ambient>0.1 0.1 0.1 1</ambient>
            <diffuse>0.1 0.1 0.1 1</diffuse>
            <specular>0 0 0 0</specular>
            <emissive>0 0 0 1</emissive>
          </material>
        </visual>
        <self_collide>0</self_collide>
        <inertial>
          <pose>0 0 0 0 -0 0</pose>
          <inertia>
            <ixx>1</ixx>
            <ixy>0</ixy>
            <ixz>0</ixz>
            <iyy>1</iyy>
            <iyz>0</iyz>
            <izz>1</izz>
          </inertia>
          <mass>1</mass>
        </inertial>
        <enable_wind>0</enable_wind>
        <kinematic>0</kinematic>
      </link>
      <joint name='left_wheel_hinge' type='revolute'>
        <pose>0 0 0 0 -0 0</pose>
        <child>left_wheel</child>
        <parent>chassis</parent>
        <axis>
          <xyz expressed_in='__model__'>0 1 0</xyz>
          <limit>
            <lower>-1e+16</lower>
            <upper>1e+16</upper>
          </limit>
          <dynamics>
            <spring_reference>0</spring_reference>
            <spring_stiffness>0</spring_stiffness>
          </dynamics>
        </axis>
      </joint>
      <joint name='right_wheel_hinge' type='revolute'>
        <pose>0 0 0 0 -0 0</pose>
        <child>right_wheel</child>
        <parent>chassis</parent>
        <axis>
          <xyz expressed_in='__model__'>0 1 0</xyz>
          <limit>
            <lower>-1e+16</lower>
            <upper>1e+16</upper>
          </limit>
          <dynamics>
            <spring_reference>0</spring_reference>
            <spring_stiffness>0</spring_stiffness>
          </dynamics>
        </axis>
      </joint>
      <link name='camera_link'>
        <gravity>0</gravity>
        <pose>0.055 0 0.0857 0 0.25 0</pose>
        <inertial>
          <mass>0.1</mass>
          <pose>0 0 0 0 -0 0</pose>
          <inertia>
            <ixx>1</ixx>
            <ixy>0</ixy>
            <ixz>0</ixz>
            <iyy>1</iyy>
            <iyz>0</iyz>
            <izz>1</izz>
          </inertia>
        </inertial>
        <visual name='visual'>
          <geometry>
            <box>
              <size>0.001 0.001 0.001</size>
            </box>
          </geometry>
        </visual>
        <sensor name='camera' type='camera'>
          <camera>
            <horizontal_fov>2.79253</horizontal_fov>
            <image>
              <width>1280</width>
              <height>720</height>
            </image>
            <clip>
              <near>0.01</near>
              <far>1</far>
            </clip>
          </camera>
          <always_on>1</always_on>
          <update_rate>10</update_rate>
          <visualize>1</visualize>
     	  <plugin name="camera_controller" filename="libgazebo_ros_camera.so">
            <alwaysOn>true</alwaysOn>
            <updateRate>0.0</updateRate>
            <cameraName>jetbot_camera</cameraName>
            <imageTopicName>image_raw</imageTopicName>
            <cameraInfoTopicName>camera_info</cameraInfoTopicName>
            <frameName>camera</frameName>
            <hackBaseline>0.07</hackBaseline>
            <distortionK1>0.0</distortionK1>
            <distortionK2>0.0</distortionK2>
            <distortionK3>0.0</distortionK3>
            <distortionT1>0.0</distortionT1>
            <distortionT2>0.0</distortionT2>
          </plugin>	
        </sensor>
        <self_collide>0</self_collide>
        <enable_wind>0</enable_wind>
        <kinematic>0</kinematic>
      </link>
      <joint name='camera_joint' type='revolute'>
        <parent>chassis</parent>
        <child>camera_link</child>
        <pose>0 0 0 0 -0 0</pose>
        <axis>
          <xyz expressed_in='__model__'>0.1 0 0</xyz>
          <limit>
            <lower>-1e+16</lower>
            <upper>1e+16</upper>
          </limit>
          <dynamics>
            <spring_reference>0</spring_reference>
            <spring_stiffness>0</spring_stiffness>
          </dynamics>
        </axis>
      </joint>
      <pose>-0.010845 -0.002525 0 0 -0 0</pose>
    </model>
    <model name='soccer_ball'>
      <static>0</static>
      <link name='soccer_ball_link'>
        <pose>0 0 0 0 -0 0</pose>
        <inertial>
          <mass>0.026</mass>
          <inertia>
            <ixx>1.664e-05</ixx>
            <iyy>1.664e-05</iyy>
            <izz>1.664e-05</izz>
            <ixy>0</ixy>
            <ixz>0</ixz>
            <iyz>0</iyz>
          </inertia>
          <pose>0 0 0 0 -0 0</pose>
        </inertial>
        <collision name='collision'>
          <geometry>
            <sphere>
              <radius>0.1</radius>
            </sphere>
          </geometry>
          <max_contacts>10</max_contacts>
          <surface>
            <contact>
              <ode/>
            </contact>
            <bounce/>
            <friction>
              <torsional>
                <ode/>
              </torsional>
              <ode/>
            </friction>
          </surface>
        </collision>
        <visual name='visual'>
          <geometry>
            <mesh>
              <scale>0.1 0.1 0.1</scale>
              <uri>model://blue_ball/meshes/ball.dae</uri>
            </mesh>
          </geometry>
        </visual>
        <self_collide>0</self_collide>
        <enable_wind>0</enable_wind>
        <kinematic>0</kinematic>
      </link>
      <pose>0.683468 -0.321067 0 0 -0 0</pose>
    </model>
    <model name='soccer_ball_0'>
      <static>0</static>
      <link name='soccer_ball_link'>
        <pose>0 0 0 0 -0 0</pose>
        <inertial>
          <mass>0.026</mass>
          <inertia>
            <ixx>1.664e-05</ixx>
            <iyy>1.664e-05</iyy>
            <izz>1.664e-05</izz>
            <ixy>0</ixy>
            <ixz>0</ixz>
            <iyz>0</iyz>
          </inertia>
          <pose>0 0 0 0 -0 0</pose>
        </inertial>
        <collision name='collision'>
          <geometry>
            <sphere>
              <radius>0.1</radius>
            </sphere>
          </geometry>
          <max_contacts>10</max_contacts>
          <surface>
            <contact>
              <ode/>
            </contact>
            <bounce/>
            <friction>
              <torsional>
                <ode/>
              </torsional>
              <ode/>
            </friction>
          </surface>
        </collision>
        <visual name='visual'>
          <geometry>
            <mesh>
              <scale>0.1 0.1 0.1</scale>
              <uri>model://red_ball/meshes/ball.dae</uri>
            </mesh>
          </geometry>
        </visual>
        <self_collide>0</self_collide>
        <enable_wind>0</enable_wind>
        <kinematic>0</kinematic>
      </link>
      <pose>0.635168 0.534699 0 0 -0 0</pose>
    </model>
    <state world_name='default'>
      <sim_time>46 295000000</sim_time>
      <real_time>71 504276500</real_time>
      <wall_time>1629672602 774513500</wall_time>
      <iterations>46295</iterations>
      <model name='JetBot'>
        <pose>-0.000442 1.8e-05 -0.000135 5e-06 -0.003582 -0.000337</pose>
        <scale>1 1 1</scale>
        <link name='camera_link'>
          <pose>0.05425 -1e-06 0.085762 5.1e-05 0.246418 -0.000324</pose>
          <velocity>-0.001919 -1.1e-05 -0.007006 -6e-06 -0.023997 -0.000274</velocity>
          <acceleration>-0.000817 -0.001073 -9.52694 -5e-06 -0.015901 -5.5e-05</acceleration>
          <wrench>-8.2e-05 -0.000107 -0.952694 0 -0 0</wrench>
        </link>
        <link name='chassis'>
          <pose>-0.000596 1.7e-05 0.042865 1.56722 -5e-06 1.57046</pose>
          <velocity>-0.00089 7e-06 -0.008322 4.7e-05 -0.023997 -0.000274</velocity>
          <acceleration>-0.000103 -0.000418 -9.52764 0.006856 -0.015908 3e-06</acceleration>
          <wrench>-0.000103 -0.000418 -9.52764 0 -0 0</wrench>
        </link>
        <link name='left_wheel'>
          <pose>0.029467 0.051257 0.029973 0.034439 -5e-06 1.57046</pose>
          <velocity>-0.000566 -1e-06 -0.007635 4.8e-05 -0.018867 -0.000274</velocity>
          <acceleration>-0.000283 0.000302 -9.59926 0.004447 -1e-06 5e-06</acceleration>
          <wrench>-0.000283 0.000302 -9.59926 0 -0 0</wrench>
        </link>
        <link name='right_wheel'>
          <pose>0.02943 -0.059493 0.029972 0.033313 -5e-06 1.57046</pose>
          <velocity>-0.000596 -1e-06 -0.007501 4.9e-05 -0.019891 -0.000274</velocity>
          <acceleration>0.000467 0.000224 -9.32041 0.006928 -2e-06 -5e-06</acceleration>
          <wrench>0.000467 0.000224 -9.32041 0 -0 0</wrench>
        </link>
      </model>
      <model name='ground_plane'>
        <pose>0 0 0 0 -0 0</pose>
        <scale>1 1 1</scale>
        <link name='link'>
          <pose>0 0 0 0 -0 0</pose>
          <velocity>0 0 0 0 -0 0</velocity>
          <acceleration>0 0 0 0 -0 0</acceleration>
          <wrench>0 0 0 0 -0 0</wrench>
        </link>
      </model>
      <model name='soccer_ball'>
        <pose>0.6 -0.6 0.1 0 -0 0</pose>
        <scale>1 1 1</scale>
        <link name='soccer_ball_link'>
          <pose>0.6 -0.6 0.1 0 -0 0</pose>
          <velocity>0 0 0 0 -0 0</velocity>
          <acceleration>0 0 0 0 -0 0</acceleration>
          <wrench>0 0 0 0 -0 0</wrench>
        </link>
      </model>
      <model name='soccer_ball_0'>
        <pose>0.6 0.6 0.1 0 -0 0</pose>
        <scale>1 1 1</scale>
        <link name='soccer_ball_link'>
          <pose>0.6 0.6 0.1 0 -0 0</pose>
          <velocity>0 0 0 0 -0 0</velocity>
          <acceleration>0 0 0 0 -0 0</acceleration>
          <wrench>0 0 0 0 -0 0</wrench>
        </link>
      </model>
      <light name='sun'>
        <pose>0 0 10 0 -0 0</pose>
      </light>
    </state>
    <gui fullscreen='0'>
      <camera name='user_camera'>
        <pose>2.42012 0.078176 1.55475 0 0.572 -3.11519</pose>
        <view_controller>orbit</view_controller>
        <projection_type>perspective</projection_type>
      </camera>
    </gui>
  </world>
</sdf>