<?xml version='1.0'?>

<sdf version='1.4'>

  <model name="diffdrive">

  <static>false</static>

  <link name='chassis'>
   <pose>0 0 0.1 0 0 0</pose>

  <inertial>
   <mass>10.0</mass>
   <pose>0.0 0 0.1 0 0 0</pose>
   <inertia>
   <ixx>0.5</ixx>
   <iyy>1.0</iyy>
   <izz>0.1</izz>
   </inertia>
   </inertial>
   <collision name='collision'>
   <geometry>
   <box>
   <size>.4 .2 .1</size>
   </box>
   </geometry>
   </collision>

  <visual name='visual'>
   <pose>0 0 0.0 0 0 0</pose>
   <geometry>
   <box>
   <size>.4 .2 .1</size>
   </box>
   </geometry>
   </visual>

   <collision name='caster_collision'>
    <pose>-0.15 0 -0.05 0 0 0</pose>
    <geometry>
    <sphere>
    <radius>.05</radius>
    </sphere>
    </geometry>

   <surface>
    <friction>
    <ode>
    <mu>0</mu>
    <mu2>0</mu2>
    <slip1>1.0</slip1>
    <slip2>1.0</slip2>
    </ode>
    </friction>
    </surface>
    </collision>

   <visual name='caster_visual'>
    <pose>-0.15 0 -0.05 0 0 0</pose>
    <geometry>
    <sphere>
    <radius>.05</radius>
    </sphere>
    </geometry>
    </visual>

   </link>

   <link name="left_wheel">
    <pose>0.1 0.13 0.1 0 1.5707 1.5707</pose>
    <collision name="collision">
    <geometry>
    <cylinder>
    <radius>.1</radius>
    <length>.05</length>
    </cylinder>
    </geometry>
    </collision>
    <visual name="visual">
    <geometry>
    <cylinder>
    <radius>.1</radius>
    <length>.05</length>
    </cylinder>
    </geometry>
    </visual>
    </link>

    <link name="right_wheel">
     <pose>0.1 -0.13 0.1 0 1.5707 1.5707</pose>
     <collision name="collision">
     <geometry>
     <cylinder>
     <radius>.1</radius>
     <length>.05</length>
     </cylinder>
     </geometry>
     </collision>
     <visual name="visual">
     <geometry>
     <cylinder>
     <radius>.1</radius>
     <length>.05</length>
     </cylinder>
     </geometry>
     </visual>
     </link>

    <joint type="revolute" name="left_wheel_hinge">
     <pose>0 0 -0.03 0 0 0</pose>
     <child>left_wheel</child>
     <parent>chassis</parent>
     <axis>
     <xyz>0 1 0</xyz>
     </axis>
    </joint>

    <joint type="revolute" name="right_wheel_hinge">
     <pose>0 0 0.03 0 0 0</pose>
     <child>right_wheel</child>
     <parent>chassis</parent>
     <axis>
     <xyz>0 1 0</xyz>
     </axis>
    </joint>

   <link name="camera_link">
   			<gravity>false</gravity>
   			<pose>0.2 0.0 0.2 0 0.1 0</pose>
   			<inertial>
   				<mass>0.1</mass>
   			</inertial>
   			<visual name="visual">
   				<geometry>
   					<box>
   						<size>0.001 0.001 0.001</size>
   					</box>
   				</geometry>
   			</visual>
   			<sensor name="camera" type="camera">
   				<camera>
   					<!--<horizontal_fov>1.047</horizontal_fov>-->
   					<horizontal_fov>2.79253</horizontal_fov>
   					<image>
   						<width>1280</width>
   						<height>720</height>
   					</image>
   					<clip>
   						<near>0.01</near>
   						<far>3</far>
   					</clip>
   					<!--<noise>
   						<type>gaussian</type>
   						<mean>0.0</mean>
   						<stddev>0.007</stddev>
   					</noise>-->
   				</camera>
   				<always_on>1</always_on>
   				<update_rate>10</update_rate>
   				<visualize>true</visualize>
   			    <plugin name="camera_controller" filename="libgazebo_ros_camera.so">
                        <alwaysOn>true</alwaysOn>
                        <updateRate>0.0</updateRate>
                        <cameraName>jetbot_camera</cameraName>
                        <imageTopicName>image_raw</imageTopicName>
                        <cameraInfoTopicName>camera_info</cameraInfoTopicName>
                        <frameName>camera</frameName>
                        <hackBaseline>0.07</hackBaseline>
                        <distortionK1>0.0</distortionK1>
                        <distortionK2>0.0</distortionK2>
                        <distortionK3>0.0</distortionK3>
                        <distortionT1>0.0</distortionT1>
                        <distortionT2>0.0</distortionT2>
                </plugin>
   			</sensor>
   		</link>

   		<joint name="camera_joint" type="revolute">
   			<parent>chassis</parent>
   			<child>camera_link</child>
   			<pose>0.0 0.0 0.0 0.0 0.0 0.0</pose>
   			<axis>
   				<xyz>0.1 0.0 0.0</xyz>
   			</axis>
   		 </joint>

   <plugin name="differential_drive_controller" filename="libgazebo_ros_diff_drive.so">
    <alwaysOn>true</alwaysOn>
    <updateRate>20</updateRate>
    <leftJoint>left_wheel_hinge</leftJoint>
    <rightJoint>right_wheel_hinge</rightJoint>
    <wheelSeparation>0.4</wheelSeparation>
    <wheelDiameter>0.1</wheelDiameter>
    <torque>20</torque>
    <commandTopic>cmd_vel</commandTopic>
    <odometryTopic>odom</odometryTopic>
    <odometryFrame>odom</odometryFrame>
    <robotBaseFrame>base_footprint</robotBaseFrame>
  </plugin>

  </model>

</sdf>
